2024-12-05 19:00:38.896 WARNING (SyncWorker_0) [homeassistant.loader] We found a custom integration gazpar which has not been tested by Home Assistant. This component might cause stability problems, be sure to disable it if you experience issues with Home Assistant
2024-12-05 19:00:38.905 WARNING (SyncWorker_0) [homeassistant.loader] We found a custom integration lg_netcast which has not been tested by Home Assistant. This component might cause stability problems, be sure to disable it if you experience issues with Home Assistant
2024-12-05 19:00:38.905 ERROR (SyncWorker_0) [homeassistant.loader] The custom integration 'lg_netcast' does not have a version key in the manifest file and was blocked from loading. See https://developers.home-assistant.io/blog/2021/01/29/custom-integration-changes#versions for more details
2024-12-05 19:00:38.909 WARNING (SyncWorker_0) [homeassistant.loader] We found a custom integration browser_mod which has not been tested by Home Assistant. This component might cause stability problems, be sure to disable it if you experience issues with Home Assistant
2024-12-05 19:00:38.912 WARNING (SyncWorker_0) [homeassistant.loader] We found a custom integration hacs which has not been tested by Home Assistant. This component might cause stability problems, be sure to disable it if you experience issues with Home Assistant
2024-12-05 19:00:38.915 WARNING (SyncWorker_0) [homeassistant.loader] We found a custom integration ping_arp which has not been tested by Home Assistant. This component might cause stability problems, be sure to disable it if you experience issues with Home Assistant
2024-12-05 19:00:38.918 WARNING (SyncWorker_0) [homeassistant.loader] We found a custom integration liveboxtvuhd which has not been tested by Home Assistant. This component might cause stability problems, be sure to disable it if you experience issues with Home Assistant
2024-12-05 19:00:38.921 WARNING (SyncWorker_0) [homeassistant.loader] We found a custom integration livebox which has not been tested by Home Assistant. This component might cause stability problems, be sure to disable it if you experience issues with Home Assistant
2024-12-05 19:00:38.926 WARNING (SyncWorker_0) [homeassistant.loader] We found a custom integration tapo_control which has not been tested by Home Assistant. This component might cause stability problems, be sure to disable it if you experience issues with Home Assistant
2024-12-05 19:00:38.929 WARNING (SyncWorker_0) [homeassistant.loader] We found a custom integration rtetempo which has not been tested by Home Assistant. This component might cause stability problems, be sure to disable it if you experience issues with Home Assistant
2024-12-05 19:00:40.719 ERROR (MainThread) [homeassistant.config_entries] Config entry 'Livebox' from integration livebox has an invalid unique_id 'False' of type bool when a string is expected, please create a bug report at https://github.com/cyr-ius/hass-livebox-component/issues
2024-12-05 19:00:40.719 ERROR (MainThread) [homeassistant.config_entries] Config entry 'Livebox' from integration livebox has an invalid unique_id 'False' of type bool when a string is expected, please create a bug report at https://github.com/cyr-ius/hass-livebox-component/issues
2024-12-05 19:00:43.860 WARNING (Recorder) [homeassistant.components.recorder.util] The system could not validate that the sqlite3 database at //config/home-assistant_v2.db was shutdown cleanly
2024-12-05 19:00:44.172 WARNING (Recorder) [homeassistant.components.recorder.util] Ended unfinished session (id=708 from 2024-12-05 17:50:43.749967)
2024-12-05 19:00:59.563 WARNING (ImportExecutor_0) [homeassistant.components.device_tracker.const] SOURCE_TYPE_ROUTER was used from ping_arp, this is a deprecated constant which will be removed in HA Core 2025.1. Use SourceType.ROUTER instead, please report it to the author of the 'ping_arp' custom integration
2024-12-05 19:01:02.640 ERROR (SyncWorker_6) [custom_components.liveboxtvuhd.client] HTTPConnectionPool(host='192.168.1.53', port=8080): Max retries exceeded with url: /remoteControl/cmd?operation=10 (Caused by ConnectTimeoutError(<urllib3.connection.HTTPConnection object at 0x7f65acb2c0>, 'Connection to 192.168.1.53 timed out. (connect timeout=3)'))
2024-12-05 19:01:03.991 ERROR (SyncWorker_5) [pygazpar.datasource] An error occurred while loading data. Retry in 3 seconds.
2024-12-05 19:01:07.637 ERROR (SyncWorker_5) [pygazpar.datasource] An error occurred while loading data. Retry in 3 seconds.
2024-12-05 19:01:09.234 WARNING (SyncWorker_6) [homeassistant.components.systemmonitor.coordinator] OS error for /media/ext, error [Errno 2] No such file or directory: '/media/ext'
2024-12-05 19:01:11.278 ERROR (SyncWorker_5) [pygazpar.datasource] An error occurred while loading data. Retry in 3 seconds.
2024-12-05 19:01:19.178 WARNING (MainThread) [homeassistant.setup] Setup of telegram_bot is taking over 10 seconds.
2024-12-05 19:01:36.438 WARNING (MainThread) [homeassistant.components.sensor] Setup of sensor platform command_line is taking over 10 seconds.
2024-12-05 19:01:40.027 WARNING (SyncWorker_2) [homeassistant.helpers.frame] Detected that custom integration 'ping_arp' accesses hass.helpers.event. This is deprecated and will stop working in Home Assistant 2025.5, it should be updated to import functions used from event directly at custom_components/ping_arp/device_tracker.py, line 106: hass.helpers.event.track_point_in_utc_time(, please report it to the author of the 'ping_arp' custom integration
2024-12-05 19:01:40.123 ERROR (MainThread) [homeassistant.helpers.event] Error while processing template: Template<template=({{ ((as_timestamp(states('sensor.cert_expiry_timestamp_external')) - as_timestamp(states.sensor.date.last_updated)) / 86400) | int }}) renders=2>
Traceback (most recent call last):
  File "/usr/src/homeassistant/homeassistant/helpers/template.py", line 2117, in forgiving_as_timestamp
    return dt_util.as_timestamp(value)
           ^^^^^^^^^^^^^^^^^^^^^^^^^^^
  File "/usr/src/homeassistant/homeassistant/util/dt.py", line 153, in as_timestamp
    raise ValueError("not a valid date/time.")
ValueError: not a valid date/time.

During handling of the above exception, another exception occurred:

Traceback (most recent call last):
  File "/usr/src/homeassistant/homeassistant/helpers/template.py", line 633, in async_render
    render_result = _render_with_context(self.template, compiled, **kwargs)
                    ^^^^^^^^^^^^^^^^^^^^^^^^^^^^^^^^^^^^^^^^^^^^^^^^^^^^^^^
  File "/usr/src/homeassistant/homeassistant/helpers/template.py", line 2735, in _render_with_context
    return template.render(**kwargs)
           ^^^^^^^^^^^^^^^^^^^^^^^^^
  File "/usr/local/lib/python3.12/site-packages/jinja2/environment.py", line 1304, in render
    self.environment.handle_exception()
  File "/usr/local/lib/python3.12/site-packages/jinja2/environment.py", line 939, in handle_exception
    raise rewrite_traceback_stack(source=source)
  File "<template>", line 1, in top-level template code
  File "/usr/local/lib/python3.12/site-packages/jinja2/sandbox.py", line 394, in call
    return __context.call(__obj, *args, **kwargs)
           ^^^^^^^^^^^^^^^^^^^^^^^^^^^^^^^^^^^^^^
  File "/usr/src/homeassistant/homeassistant/helpers/template.py", line 2120, in forgiving_as_timestamp
    raise_no_default("as_timestamp", value)
  File "/usr/src/homeassistant/homeassistant/helpers/template.py", line 1911, in raise_no_default
    raise ValueError(
ValueError: Template error: as_timestamp got invalid input 'unavailable' when rendering template '{{ ((as_timestamp(states('sensor.cert_expiry_timestamp_external')) - as_timestamp(states.sensor.date.last_updated)) / 86400) | int }}' but no default was specified

The above exception was the direct cause of the following exception:

Traceback (most recent call last):
  File "/usr/src/homeassistant/homeassistant/helpers/template.py", line 750, in async_render_to_info
    render_info._result = self.async_render(  # noqa: SLF001
                          ^^^^^^^^^^^^^^^^^^^^^^^^^^^^^^^^^^
  File "/usr/src/homeassistant/homeassistant/helpers/template.py", line 635, in async_render
    raise TemplateError(err) from err
homeassistant.exceptions.TemplateError: ValueError: Template error: as_timestamp got invalid input 'unavailable' when rendering template '{{ ((as_timestamp(states('sensor.cert_expiry_timestamp_external')) - as_timestamp(states.sensor.date.last_updated)) / 86400) | int }}' but no default was specified
2024-12-05 19:01:40.143 ERROR (MainThread) [homeassistant.components.template.template_entity] TemplateError('ValueError: Template error: as_timestamp got invalid input 'unavailable' when rendering template '{{ ((as_timestamp(states('sensor.cert_expiry_timestamp_external')) - as_timestamp(states.sensor.date.last_updated)) / 86400) | int }}' but no default was specified') while processing template 'Template<template=({{ ((as_timestamp(states('sensor.cert_expiry_timestamp_external')) - as_timestamp(states.sensor.date.last_updated)) / 86400) | int }}) renders=4>' for attribute '_attr_native_value' in entity 'sensor.s_cert_exiry_d'
2024-12-05 19:01:40.147 ERROR (MainThread) [homeassistant.core] Error running job: <Job onetime listen homeassistant_start <function _async_at_core_state.<locals>._matched_event at 0x7f6fe199e0> HassJobType.Callback <_OneTimeListener homeassistant.helpers.start:<function _async_at_core_state.<locals>._matched_event at 0x7f6fe199e0>>>
Traceback (most recent call last):
  File "/usr/src/homeassistant/homeassistant/components/sensor/__init__.py", line 659, in state
    numerical_value = int(value)
                      ^^^^^^^^^^
ValueError: invalid literal for int() with base 10: 'unknown'

During handling of the above exception, another exception occurred:

Traceback (most recent call last):
  File "/usr/src/homeassistant/homeassistant/components/sensor/__init__.py", line 662, in state
    numerical_value = float(value)
                      ^^^^^^^^^^^^
ValueError: could not convert string to float: 'unknown'

The above exception was the direct cause of the following exception:

Traceback (most recent call last):
  File "/usr/src/homeassistant/homeassistant/core.py", line 1587, in async_fire_internal
    self._hass.async_run_hass_job(job, event)
  File "/usr/src/homeassistant/homeassistant/core.py", line 949, in async_run_hass_job
    hassjob.target(*args)
  File "/usr/src/homeassistant/homeassistant/core.py", line 1448, in __call__
    self.hass.async_run_hass_job(self.listener_job, event)
  File "/usr/src/homeassistant/homeassistant/core.py", line 949, in async_run_hass_job
    hassjob.target(*args)
  File "/usr/src/homeassistant/homeassistant/helpers/start.py", line 44, in _matched_event
    hass.async_run_hass_job(at_start_job, hass)
  File "/usr/src/homeassistant/homeassistant/core.py", line 949, in async_run_hass_job
    hassjob.target(*args)
  File "/usr/src/homeassistant/homeassistant/components/template/template_entity.py", line 517, in _async_template_startup
    result_info.async_refresh()
  File "/usr/src/homeassistant/homeassistant/helpers/event.py", line 1133, in async_refresh
    self._refresh(None)
  File "/usr/src/homeassistant/homeassistant/helpers/event.py", line 1319, in _refresh
    self.hass.async_run_hass_job(self._job, event, updates)
  File "/usr/src/homeassistant/homeassistant/core.py", line 949, in async_run_hass_job
    hassjob.target(*args)
  File "/usr/src/homeassistant/homeassistant/components/template/template_entity.py", line 463, in _handle_results
    self.async_write_ha_state()
  File "/usr/src/homeassistant/homeassistant/helpers/entity.py", line 1007, in async_write_ha_state
    self._async_write_ha_state()
  File "/usr/src/homeassistant/homeassistant/helpers/entity.py", line 1132, in _async_write_ha_state
    self.__async_calculate_state()
  File "/usr/src/homeassistant/homeassistant/helpers/entity.py", line 1069, in __async_calculate_state
    state = self._stringify_state(available)
            ^^^^^^^^^^^^^^^^^^^^^^^^^^^^^^^^
  File "/usr/src/homeassistant/homeassistant/helpers/entity.py", line 1013, in _stringify_state
    if (state := self.state) is None:
                 ^^^^^^^^^^
  File "/usr/src/homeassistant/homeassistant/components/sensor/__init__.py", line 666, in state
    raise ValueError(
ValueError: Sensor sensor.niveau_encre_noire_preserved has device class 'None', state class 'None' unit '%' and suggested precision 'None' thus indicating it has a numeric value; however, it has the non-numeric value: 'unknown' (<class 'str'>)
2024-12-05 19:01:40.168 ERROR (MainThread) [homeassistant.core] Error running job: <Job onetime listen homeassistant_start <function _async_at_core_state.<locals>._matched_event at 0x7f6fe191c0> HassJobType.Callback <_OneTimeListener homeassistant.helpers.start:<function _async_at_core_state.<locals>._matched_event at 0x7f6fe191c0>>>
Traceback (most recent call last):
  File "/usr/src/homeassistant/homeassistant/components/sensor/__init__.py", line 659, in state
    numerical_value = int(value)
                      ^^^^^^^^^^
ValueError: invalid literal for int() with base 10: 'unknown'

During handling of the above exception, another exception occurred:

Traceback (most recent call last):
  File "/usr/src/homeassistant/homeassistant/components/sensor/__init__.py", line 662, in state
    numerical_value = float(value)
                      ^^^^^^^^^^^^
ValueError: could not convert string to float: 'unknown'

The above exception was the direct cause of the following exception:

Traceback (most recent call last):
  File "/usr/src/homeassistant/homeassistant/core.py", line 1587, in async_fire_internal
    self._hass.async_run_hass_job(job, event)
  File "/usr/src/homeassistant/homeassistant/core.py", line 949, in async_run_hass_job
    hassjob.target(*args)
  File "/usr/src/homeassistant/homeassistant/core.py", line 1448, in __call__
    self.hass.async_run_hass_job(self.listener_job, event)
  File "/usr/src/homeassistant/homeassistant/core.py", line 949, in async_run_hass_job
    hassjob.target(*args)
  File "/usr/src/homeassistant/homeassistant/helpers/start.py", line 44, in _matched_event
    hass.async_run_hass_job(at_start_job, hass)
  File "/usr/src/homeassistant/homeassistant/core.py", line 949, in async_run_hass_job
    hassjob.target(*args)
  File "/usr/src/homeassistant/homeassistant/components/template/template_entity.py", line 517, in _async_template_startup
    result_info.async_refresh()
  File "/usr/src/homeassistant/homeassistant/helpers/event.py", line 1133, in async_refresh
    self._refresh(None)
  File "/usr/src/homeassistant/homeassistant/helpers/event.py", line 1319, in _refresh
    self.hass.async_run_hass_job(self._job, event, updates)
  File "/usr/src/homeassistant/homeassistant/core.py", line 949, in async_run_hass_job
    hassjob.target(*args)
  File "/usr/src/homeassistant/homeassistant/components/template/template_entity.py", line 463, in _handle_results
    self.async_write_ha_state()
  File "/usr/src/homeassistant/homeassistant/helpers/entity.py", line 1007, in async_write_ha_state
    self._async_write_ha_state()
  File "/usr/src/homeassistant/homeassistant/helpers/entity.py", line 1132, in _async_write_ha_state
    self.__async_calculate_state()
  File "/usr/src/homeassistant/homeassistant/helpers/entity.py", line 1069, in __async_calculate_state
    state = self._stringify_state(available)
            ^^^^^^^^^^^^^^^^^^^^^^^^^^^^^^^^
  File "/usr/src/homeassistant/homeassistant/helpers/entity.py", line 1013, in _stringify_state
    if (state := self.state) is None:
                 ^^^^^^^^^^
  File "/usr/src/homeassistant/homeassistant/components/sensor/__init__.py", line 666, in state
    raise ValueError(
ValueError: Sensor sensor.niveau_encre_couleur_preserved has device class 'None', state class 'None' unit '%' and suggested precision 'None' thus indicating it has a numeric value; however, it has the non-numeric value: 'unknown' (<class 'str'>)
2024-12-05 19:01:40.177 ERROR (MainThread) [homeassistant.core] Error running job: <Job onetime listen homeassistant_start <function _async_at_core_state.<locals>._matched_event at 0x7f6fe18f40> HassJobType.Callback <_OneTimeListener homeassistant.helpers.start:<function _async_at_core_state.<locals>._matched_event at 0x7f6fe18f40>>>
Traceback (most recent call last):
  File "/usr/src/homeassistant/homeassistant/components/sensor/__init__.py", line 659, in state
    numerical_value = int(value)
                      ^^^^^^^^^^
ValueError: invalid literal for int() with base 10: 'unknown'

During handling of the above exception, another exception occurred:

Traceback (most recent call last):
  File "/usr/src/homeassistant/homeassistant/components/sensor/__init__.py", line 662, in state
    numerical_value = float(value)
                      ^^^^^^^^^^^^
ValueError: could not convert string to float: 'unknown'

The above exception was the direct cause of the following exception:

Traceback (most recent call last):
  File "/usr/src/homeassistant/homeassistant/core.py", line 1587, in async_fire_internal
    self._hass.async_run_hass_job(job, event)
  File "/usr/src/homeassistant/homeassistant/core.py", line 949, in async_run_hass_job
    hassjob.target(*args)
  File "/usr/src/homeassistant/homeassistant/core.py", line 1448, in __call__
    self.hass.async_run_hass_job(self.listener_job, event)
  File "/usr/src/homeassistant/homeassistant/core.py", line 949, in async_run_hass_job
    hassjob.target(*args)
  File "/usr/src/homeassistant/homeassistant/helpers/start.py", line 44, in _matched_event
    hass.async_run_hass_job(at_start_job, hass)
  File "/usr/src/homeassistant/homeassistant/core.py", line 949, in async_run_hass_job
    hassjob.target(*args)
  File "/usr/src/homeassistant/homeassistant/components/template/template_entity.py", line 517, in _async_template_startup
    result_info.async_refresh()
  File "/usr/src/homeassistant/homeassistant/helpers/event.py", line 1133, in async_refresh
    self._refresh(None)
  File "/usr/src/homeassistant/homeassistant/helpers/event.py", line 1319, in _refresh
    self.hass.async_run_hass_job(self._job, event, updates)
  File "/usr/src/homeassistant/homeassistant/core.py", line 949, in async_run_hass_job
    hassjob.target(*args)
  File "/usr/src/homeassistant/homeassistant/components/template/template_entity.py", line 463, in _handle_results
    self.async_write_ha_state()
  File "/usr/src/homeassistant/homeassistant/helpers/entity.py", line 1007, in async_write_ha_state
    self._async_write_ha_state()
  File "/usr/src/homeassistant/homeassistant/helpers/entity.py", line 1132, in _async_write_ha_state
    self.__async_calculate_state()
  File "/usr/src/homeassistant/homeassistant/helpers/entity.py", line 1069, in __async_calculate_state
    state = self._stringify_state(available)
            ^^^^^^^^^^^^^^^^^^^^^^^^^^^^^^^^
  File "/usr/src/homeassistant/homeassistant/helpers/entity.py", line 1013, in _stringify_state
    if (state := self.state) is None:
                 ^^^^^^^^^^
  File "/usr/src/homeassistant/homeassistant/components/sensor/__init__.py", line 666, in state
    raise ValueError(
ValueError: Sensor sensor.temp_piscine_preserved has device class 'None', state class 'None' unit '°C' and suggested precision 'None' thus indicating it has a numeric value; however, it has the non-numeric value: 'unknown' (<class 'str'>)
2024-12-05 19:01:40.199 ERROR (MainThread) [homeassistant.helpers.event] Error while processing template: Template<template=({{ (states('sensor.niveau_encre_couleur_preserved') | int) <= 5 or (states('sensor.niveau_encre_noire_preserved') | int) <= 5 }}) renders=2>
Traceback (most recent call last):
  File "/usr/src/homeassistant/homeassistant/helpers/template.py", line 633, in async_render
    render_result = _render_with_context(self.template, compiled, **kwargs)
                    ^^^^^^^^^^^^^^^^^^^^^^^^^^^^^^^^^^^^^^^^^^^^^^^^^^^^^^^
  File "/usr/src/homeassistant/homeassistant/helpers/template.py", line 2735, in _render_with_context
    return template.render(**kwargs)
           ^^^^^^^^^^^^^^^^^^^^^^^^^
  File "/usr/local/lib/python3.12/site-packages/jinja2/environment.py", line 1304, in render
    self.environment.handle_exception()
  File "/usr/local/lib/python3.12/site-packages/jinja2/environment.py", line 939, in handle_exception
    raise rewrite_traceback_stack(source=source)
  File "<template>", line 1, in top-level template code
  File "/usr/src/homeassistant/homeassistant/helpers/template.py", line 2373, in forgiving_int_filter
    raise_no_default("int", value)
  File "/usr/src/homeassistant/homeassistant/helpers/template.py", line 1911, in raise_no_default
    raise ValueError(
ValueError: Template error: int got invalid input 'unknown' when rendering template '{{ (states('sensor.niveau_encre_couleur_preserved') | int) <= 5 or (states('sensor.niveau_encre_noire_preserved') | int) <= 5 }}' but no default was specified

The above exception was the direct cause of the following exception:

Traceback (most recent call last):
  File "/usr/src/homeassistant/homeassistant/helpers/template.py", line 750, in async_render_to_info
    render_info._result = self.async_render(  # noqa: SLF001
                          ^^^^^^^^^^^^^^^^^^^^^^^^^^^^^^^^^^
  File "/usr/src/homeassistant/homeassistant/helpers/template.py", line 635, in async_render
    raise TemplateError(err) from err
homeassistant.exceptions.TemplateError: ValueError: Template error: int got invalid input 'unknown' when rendering template '{{ (states('sensor.niveau_encre_couleur_preserved') | int) <= 5 or (states('sensor.niveau_encre_noire_preserved') | int) <= 5 }}' but no default was specified
2024-12-05 19:01:40.203 ERROR (MainThread) [homeassistant.components.template.template_entity] TemplateError('ValueError: Template error: int got invalid input 'unknown' when rendering template '{{ (states('sensor.niveau_encre_couleur_preserved') | int) <= 5 or (states('sensor.niveau_encre_noire_preserved') | int) <= 5 }}' but no default was specified') while processing template 'Template<template=({{ (states('sensor.niveau_encre_couleur_preserved') | int) <= 5 or (states('sensor.niveau_encre_noire_preserved') | int) <= 5 }}) renders=4>' for attribute '_state' in entity 'binary_sensor.cartouche_imprimante_low'
2024-12-05 19:01:42.308 ERROR (MainThread) [homeassistant.components.google_assistant.http] Request for https://homegraph.googleapis.com/v1/devices:requestSync failed: 500
2024-12-05 19:01:42.491 ERROR (MainThread) [homeassistant.components.netatmo] Error during webhook registration - ("400 - Bad request - Allowed ports for webhooks are 80, 88, 443 and 9443. (21) when accessing 'https://api.netatmo.com/api/addwebhook'",)
2024-12-05 19:01:42.501 ERROR (MainThread) [homeassistant.components.cert_expiry.coordinator] Error fetching biot.questroy.com:18123 data: Connection refused by server: biot.questroy.com:18123
2024-12-05 19:02:04.399 WARNING (MainThread) [homeassistant.components.automation.screenshot_cam_sud] Screenshot Cam: Already running
2024-12-05 19:02:07.037 WARNING (MainThread) [homeassistant.helpers.entity] Update of camera.camera_porte_hd_stream is taking over 10 seconds
2024-12-05 19:02:35.091 ERROR (MainThread) [homeassistant.components.ipp.coordinator] Error fetching ipp data: Invalid response from API: Timeout occurred while connecting to IPP server.
2024-12-05 19:02:36.399 WARNING (MainThread) [homeassistant.components.automation.screenshot_cam_sud] Screenshot Cam: Already running
2024-12-05 19:02:39.522 ERROR (MainThread) [homeassistant.helpers.event] Error while processing template: Template<template=({% if states(entity) | int < 20 %}
red
{% else %}
#b4befe
{% endif %}) renders=2>
Traceback (most recent call last):
  File "/usr/src/homeassistant/homeassistant/helpers/template.py", line 633, in async_render
    render_result = _render_with_context(self.template, compiled, **kwargs)
                    ^^^^^^^^^^^^^^^^^^^^^^^^^^^^^^^^^^^^^^^^^^^^^^^^^^^^^^^
  File "/usr/src/homeassistant/homeassistant/helpers/template.py", line 2735, in _render_with_context
    return template.render(**kwargs)
           ^^^^^^^^^^^^^^^^^^^^^^^^^
  File "/usr/local/lib/python3.12/site-packages/jinja2/environment.py", line 1304, in render
    self.environment.handle_exception()
  File "/usr/local/lib/python3.12/site-packages/jinja2/environment.py", line 939, in handle_exception
    raise rewrite_traceback_stack(source=source)
  File "<template>", line 1, in top-level template code
  File "/usr/src/homeassistant/homeassistant/helpers/template.py", line 2373, in forgiving_int_filter
    raise_no_default("int", value)
  File "/usr/src/homeassistant/homeassistant/helpers/template.py", line 1911, in raise_no_default
    raise ValueError(
ValueError: Template error: int got invalid input 'unavailable' when rendering template '{% if states(entity) | int < 20 %}
red
{% else %}
#b4befe
{% endif %}' but no default was specified

The above exception was the direct cause of the following exception:

Traceback (most recent call last):
  File "/usr/src/homeassistant/homeassistant/helpers/template.py", line 750, in async_render_to_info
    render_info._result = self.async_render(  # noqa: SLF001
                          ^^^^^^^^^^^^^^^^^^^^^^^^^^^^^^^^^^
  File "/usr/src/homeassistant/homeassistant/helpers/template.py", line 635, in async_render
    raise TemplateError(err) from err
homeassistant.exceptions.TemplateError: ValueError: Template error: int got invalid input 'unavailable' when rendering template '{% if states(entity) | int < 20 %}
red
{% else %}
#b4befe
{% endif %}' but no default was specified
2024-12-05 19:03:14.441 WARNING (MainThread) [homeassistant.components.automation.screenshot_cam_sud] Screenshot Cam: Already running
2024-12-05 19:04:44.398 WARNING (MainThread) [homeassistant.components.automation.screenshot_cam_sud] Screenshot Cam: Already running
2024-12-05 19:04:46.399 WARNING (MainThread) [homeassistant.components.automation.screenshot_cam_sud] Screenshot Cam: Already running
2024-12-05 19:04:48.398 WARNING (MainThread) [homeassistant.components.automation.screenshot_cam_sud] Screenshot Cam: Already running
2024-12-05 19:04:48.537 ERROR (MainThread) [homeassistant.components.generic.camera] Error getting new camera image from Cam Sud: Client error '404 Not Found' for url 'http://192.168.1.186:8123/local/camera/sud.jpg'
For more information check: https://developer.mozilla.org/en-US/docs/Web/HTTP/Status/404
2024-12-05 19:06:24.327 WARNING (MainThread) [homeassistant.components.waze_travel_time] Error on retrieving data: <html>
<head><title>503 Service Temporarily Unavailable</title></head>
<body>
<center><h1>503 Service Temporarily Unavailable</h1></center>
<hr><center>nginx</center>
</body>
</html>

2024-12-05 19:06:24.345 WARNING (MainThread) [homeassistant.components.waze_travel_time.sensor] No routes found
2024-12-05 19:06:45.178 WARNING (MainThread) [homeassistant.components.automation.screenshot_cam_sud] Screenshot Cam: Already running
2024-12-05 19:07:14.399 WARNING (MainThread) [homeassistant.components.automation.screenshot_cam_sud] Screenshot Cam: Already running
2024-12-05 19:07:16.624 WARNING (MainThread) [homeassistant.components.automation.screenshot_cam_sud] Screenshot Cam: Already running
2024-12-05 19:07:32.610 WARNING (MainThread) [py.warnings] /usr/local/lib/python3.12/site-packages/turbojpeg.py:940: UserWarning: Premature end of JPEG file
  warnings.warn(self.__get_error_string(handle))

2024-12-05 19:08:01.668 ERROR (MainThread) [homeassistant.components.ipp.coordinator] Error fetching ipp data: Invalid response from API: Timeout occurred while connecting to IPP server.
2024-12-05 19:08:33.181 ERROR (MainThread) [frontend.js.modern.202411062] Uncaught error from Chrome WebView 130.0.6723.107 on Android 14
Script error.
null
@:0:0
2024-12-05 19:09:24.623 WARNING (MainThread) [py.warnings] /usr/local/lib/python3.12/site-packages/turbojpeg.py:940: UserWarning: Premature end of JPEG file
  warnings.warn(self.__get_error_string(handle))

2024-12-05 19:09:48.552 WARNING (MainThread) [py.warnings] /usr/local/lib/python3.12/site-packages/turbojpeg.py:940: UserWarning: Premature end of JPEG file
  warnings.warn(self.__get_error_string(handle))

2024-12-05 19:10:12.532 ERROR (MainThread) [aiohttp.server] Unhandled exception
Traceback (most recent call last):
  File "/usr/local/lib/python3.12/site-packages/aiohttp/web_protocol.py", line 560, in start
    resp, reset = await task
                  ^^^^^^^^^^
  File "/usr/local/lib/python3.12/site-packages/aiohttp/web_protocol.py", line 502, in _handle_request
    resp, reset = await self.finish_response(request, resp, start_time)
                  ^^^^^^^^^^^^^^^^^^^^^^^^^^^^^^^^^^^^^^^^^^^^^^^^^^^^^
  File "/usr/local/lib/python3.12/site-packages/aiohttp/web_protocol.py", line 668, in finish_response
    await prepare_meth(request)
  File "/usr/local/lib/python3.12/site-packages/aiohttp/web_fileresponse.py", line 351, in prepare
    fobj = await loop.run_in_executor(None, file_path.open, "rb")
           ^^^^^^^^^^^^^^^^^^^^^^^^^^^^^^^^^^^^^^^^^^^^^^^^^^^^^^
  File "/usr/local/lib/python3.12/concurrent/futures/thread.py", line 58, in run
    result = self.fn(*self.args, **self.kwargs)
             ^^^^^^^^^^^^^^^^^^^^^^^^^^^^^^^^^^
  File "/usr/src/homeassistant/homeassistant/util/loop.py", line 200, in protected_loop_func
    return func(*args, **kwargs)
           ^^^^^^^^^^^^^^^^^^^^^
  File "/usr/local/lib/python3.12/pathlib.py", line 1013, in open
    return io.open(self, mode, buffering, encoding, errors, newline)
           ^^^^^^^^^^^^^^^^^^^^^^^^^^^^^^^^^^^^^^^^^^^^^^^^^^^^^^^^^
FileNotFoundError: [Errno 2] No such file or directory: '/config/www/camera/nord.jpg'
2024-12-05 19:10:12.594 ERROR (MainThread) [homeassistant.components.generic.camera] Error getting new camera image from Cam Nord: Server disconnected without sending a response.
2024-12-05 19:11:00.535 ERROR (MainThread) [homeassistant.components.generic.camera] Error getting new camera image from Cam Nord: Client error '404 Not Found' for url 'http://192.168.1.186:8123/local/camera/nord.jpg'
For more information check: https://developer.mozilla.org/en-US/docs/Web/HTTP/Status/404
2024-12-05 19:12:32.528 ERROR (MainThread) [frontend.js.modern.202411062] Uncaught error from Chrome WebView 130.0.6723.107 on Android 14
Script error.
null
@:0:0
2024-12-05 19:12:40.549 WARNING (MainThread) [py.warnings] /usr/local/lib/python3.12/site-packages/turbojpeg.py:940: UserWarning: Premature end of JPEG file
  warnings.warn(self.__get_error_string(handle))

2024-12-05 19:14:06.399 WARNING (MainThread) [homeassistant.components.automation.screenshot_cam_sud] Screenshot Cam: Already running
2024-12-05 19:14:08.399 WARNING (MainThread) [homeassistant.components.automation.screenshot_cam_sud] Screenshot Cam: Already running
2024-12-05 19:16:32.105 ERROR (MainThread) [frontend.js.modern.202411062] Uncaught error from Chrome WebView 130.0.6723.107 on Android 14
Script error.
null
@:0:0
2024-12-05 19:16:34.057 WARNING (MainThread) [homeassistant.helpers.entity] Update of sensor.waze_travel_time is taking over 10 seconds
2024-12-05 19:20:02.940 WARNING (MainThread) [py.warnings] /usr/local/lib/python3.12/site-packages/turbojpeg.py:940: UserWarning: Premature end of JPEG file
  warnings.warn(self.__get_error_string(handle))

2024-12-05 19:20:32.007 ERROR (MainThread) [frontend.js.modern.202411062] Uncaught error from Chrome WebView 130.0.6723.107 on Android 14
Script error.
null
@:0:0
2024-12-05 19:24:31.164 ERROR (MainThread) [frontend.js.modern.202411062] Uncaught error from Chrome WebView 130.0.6723.107 on Android 14
Script error.
null
@:0:0
2024-12-05 19:26:34.058 WARNING (MainThread) [homeassistant.helpers.entity] Update of sensor.waze_travel_time is taking over 10 seconds
2024-12-05 19:27:04.710 WARNING (MainThread) [py.warnings] /usr/local/lib/python3.12/site-packages/turbojpeg.py:940: UserWarning: Premature end of JPEG file
  warnings.warn(self.__get_error_string(handle))

2024-12-05 19:27:23.458 ERROR (MainThread) [frontend.js.modern.202411062] Uncaught error from Chrome WebView 130.0.6723.107 on Android 14
Script error.
null
@:0:0
2024-12-05 19:28:32.116 ERROR (MainThread) [frontend.js.modern.202411062] Uncaught error from Chrome WebView 130.0.6723.107 on Android 14
Script error.
null
@:0:0
2024-12-05 19:31:34.059 WARNING (MainThread) [homeassistant.helpers.entity] Update of sensor.waze_travel_time is taking over 10 seconds
2024-12-05 19:32:08.905 WARNING (MainThread) [homeassistant.components.automation.screenshot_cam_sud] Screenshot Cam: Already running
2024-12-05 19:32:31.048 ERROR (MainThread) [frontend.js.modern.202411062] Uncaught error from Chrome WebView 130.0.6723.107 on Android 14
Script error.
null
@:0:0
2024-12-05 19:36:31.959 ERROR (MainThread) [frontend.js.modern.202411062] Uncaught error from Chrome WebView 130.0.6723.107 on Android 14
Script error.
null
@:0:0
2024-12-05 19:40:26.399 WARNING (MainThread) [homeassistant.components.automation.screenshot_cam_sud] Screenshot Cam: Already running
2024-12-05 19:40:28.649 WARNING (MainThread) [homeassistant.components.automation.screenshot_cam_sud] Screenshot Cam: Already running
2024-12-05 19:40:32.321 ERROR (MainThread) [frontend.js.modern.202411062] Uncaught error from Chrome WebView 130.0.6723.107 on Android 14
Script error.
null
@:0:0
2024-12-05 19:44:28.708 WARNING (MainThread) [py.warnings] /usr/local/lib/python3.12/site-packages/turbojpeg.py:940: UserWarning: Premature end of JPEG file
  warnings.warn(self.__get_error_string(handle))

2024-12-05 19:44:32.222 ERROR (MainThread) [frontend.js.modern.202411062] Uncaught error from Chrome WebView 130.0.6723.107 on Android 14
Script error.
null
@:0:0
2024-12-05 19:45:02.868 ERROR (MainThread) [frontend.js.modern.202411062] Uncaught error from Chrome WebView 130.0.6723.107 on Android 14
Script error.
null
@:0:0
2024-12-05 19:46:24.338 WARNING (MainThread) [homeassistant.components.waze_travel_time] Error on retrieving data: <html>
<head><title>503 Service Temporarily Unavailable</title></head>
<body>
<center><h1>503 Service Temporarily Unavailable</h1></center>
<hr><center>nginx</center>
</body>
</html>

2024-12-05 19:46:24.338 WARNING (MainThread) [homeassistant.components.waze_travel_time.sensor] No routes found
2024-12-05 19:47:24.399 WARNING (MainThread) [homeassistant.components.automation.screenshot_cam_sud] Screenshot Cam: Already running
2024-12-05 19:47:26.399 WARNING (MainThread) [homeassistant.components.automation.screenshot_cam_sud] Screenshot Cam: Already running
2024-12-05 19:47:29.511 WARNING (MainThread) [homeassistant.components.automation.screenshot_cam_sud] Screenshot Cam: Already running
2024-12-05 19:47:45.045 ERROR (MainThread) [aiohttp.server] Unhandled exception
Traceback (most recent call last):
  File "/usr/src/homeassistant/homeassistant/components/websocket_api/http.py", line 347, in async_handle
    await self._async_websocket_command_phase(connection, send_bytes_text)
  File "/usr/src/homeassistant/homeassistant/components/websocket_api/http.py", line 469, in _async_websocket_command_phase
    msg = await wsock.receive()
          ^^^^^^^^^^^^^^^^^^^^^
  File "/usr/local/lib/python3.12/site-packages/aiohttp/web_ws.py", line 513, in receive
    msg = await self._reader.read()
          ^^^^^^^^^^^^^^^^^^^^^^^^^
  File "/usr/local/lib/python3.12/site-packages/aiohttp/streams.py", line 685, in read
    return await super().read()
           ^^^^^^^^^^^^^^^^^^^^
  File "/usr/local/lib/python3.12/site-packages/aiohttp/streams.py", line 644, in read
    await self._waiter
asyncio.exceptions.CancelledError

During handling of the above exception, another exception occurred:

Traceback (most recent call last):
  File "/usr/local/lib/python3.12/site-packages/aiohttp/web_protocol.py", line 477, in _handle_request
    resp = await request_handler(request)
           ^^^^^^^^^^^^^^^^^^^^^^^^^^^^^^
  File "/usr/local/lib/python3.12/site-packages/aiohttp/web_app.py", line 567, in _handle
    return await handler(request)
           ^^^^^^^^^^^^^^^^^^^^^^
  File "/usr/local/lib/python3.12/site-packages/aiohttp/web_middlewares.py", line 117, in impl
    return await handler(request)
           ^^^^^^^^^^^^^^^^^^^^^^
  File "/usr/src/homeassistant/homeassistant/components/http/security_filter.py", line 92, in security_filter_middleware
    return await handler(request)
           ^^^^^^^^^^^^^^^^^^^^^^
  File "/usr/src/homeassistant/homeassistant/components/http/forwarded.py", line 83, in forwarded_middleware
    return await handler(request)
           ^^^^^^^^^^^^^^^^^^^^^^
  File "/usr/src/homeassistant/homeassistant/components/http/request_context.py", line 26, in request_context_middleware
    return await handler(request)
           ^^^^^^^^^^^^^^^^^^^^^^
  File "/usr/src/homeassistant/homeassistant/components/http/ban.py", line 86, in ban_middleware
    return await handler(request)
           ^^^^^^^^^^^^^^^^^^^^^^
  File "/usr/src/homeassistant/homeassistant/components/http/auth.py", line 242, in auth_middleware
    return await handler(request)
           ^^^^^^^^^^^^^^^^^^^^^^
  File "/usr/src/homeassistant/homeassistant/components/http/headers.py", line 32, in headers_middleware
    response = await handler(request)
               ^^^^^^^^^^^^^^^^^^^^^^
  File "/usr/src/homeassistant/homeassistant/helpers/http.py", line 73, in handle
    result = await handler(request, **request.match_info)
             ^^^^^^^^^^^^^^^^^^^^^^^^^^^^^^^^^^^^^^^^^^^^
  File "/usr/src/homeassistant/homeassistant/components/websocket_api/http.py", line 55, in get
    return await WebSocketHandler(request.app[KEY_HASS], request).async_handle()
           ^^^^^^^^^^^^^^^^^^^^^^^^^^^^^^^^^^^^^^^^^^^^^^^^^^^^^^^^^^^^^^^^^^^^^
  File "/usr/src/homeassistant/homeassistant/components/websocket_api/http.py", line 372, in async_handle
    await self._async_cleanup_writer_and_close(disconnect_warn, connection)
  File "/usr/src/homeassistant/homeassistant/components/websocket_api/http.py", line 520, in _async_cleanup_writer_and_close
    await wsock.close()
  File "/usr/local/lib/python3.12/site-packages/aiohttp/web_ws.py", line 457, in close
    msg = await reader.read()
          ^^^^^^^^^^^^^^^^^^^
  File "/usr/local/lib/python3.12/site-packages/aiohttp/streams.py", line 685, in read
    return await super().read()
           ^^^^^^^^^^^^^^^^^^^^
  File "/usr/local/lib/python3.12/site-packages/aiohttp/streams.py", line 644, in read
    await self._waiter
asyncio.exceptions.CancelledError

During handling of the above exception, another exception occurred:

Traceback (most recent call last):
  File "/usr/local/lib/python3.12/site-packages/aiohttp/web_protocol.py", line 560, in start
    resp, reset = await task
                  ^^^^^^^^^^
  File "/usr/local/lib/python3.12/site-packages/aiohttp/web_protocol.py", line 506, in _handle_request
    self._handler_waiter.set_result(None)
asyncio.exceptions.InvalidStateError: invalid state
